[2025-06-07T10:52:18.662+0000] {taskinstance.py:1956} INFO - Dependencies all met for dep_context=non-requeueable deps ti=<TaskInstance: ecommerce_data_ingestion.wait_for_olist_customers_dataset scheduled__2025-06-06T01:00:00+00:00 [queued]>
[2025-06-07T10:52:18.894+0000] {taskinstance.py:1956} INFO - Dependencies all met for dep_context=requeueable deps ti=<TaskInstance: ecommerce_data_ingestion.wait_for_olist_customers_dataset scheduled__2025-06-06T01:00:00+00:00 [queued]>
[2025-06-07T10:52:18.936+0000] {taskinstance.py:2170} INFO - Starting attempt 1 of 2
[2025-06-07T10:52:19.363+0000] {taskinstance.py:2191} INFO - Executing <Task(FileSensor): wait_for_olist_customers_dataset> on 2025-06-06 01:00:00+00:00
[2025-06-07T10:52:19.473+0000] {standard_task_runner.py:60} INFO - Started process 296 to run task
[2025-06-07T10:52:19.567+0000] {standard_task_runner.py:87} INFO - Running: ['***', 'tasks', 'run', 'ecommerce_data_ingestion', 'wait_for_olist_customers_dataset', 'scheduled__2025-06-06T01:00:00+00:00', '--job-id', '24', '--raw', '--subdir', 'DAGS_FOLDER/ecommerce_etl_dag.py', '--cfg-path', '/tmp/tmpkegf39oq']
[2025-06-07T10:52:19.681+0000] {standard_task_runner.py:88} INFO - Job 24: Subtask wait_for_olist_customers_dataset
[2025-06-07T10:52:20.425+0000] {task_command.py:423} INFO - Running <TaskInstance: ecommerce_data_ingestion.wait_for_olist_customers_dataset scheduled__2025-06-06T01:00:00+00:00 [running]> on host ab0825485965
[2025-06-07T10:52:21.520+0000] {taskinstance.py:2480} INFO - Exporting env vars: AIRFLOW_CTX_DAG_OWNER='***' AIRFLOW_CTX_DAG_ID='ecommerce_data_ingestion' AIRFLOW_CTX_TASK_ID='wait_for_olist_customers_dataset' AIRFLOW_CTX_EXECUTION_DATE='2025-06-06T01:00:00+00:00' AIRFLOW_CTX_TRY_NUMBER='1' AIRFLOW_CTX_DAG_RUN_ID='scheduled__2025-06-06T01:00:00+00:00'
[2025-06-07T10:52:21.640+0000] {taskinstance.py:2698} ERROR - Task failed with exception
Traceback (most recent call last):
  File "/home/airflow/.local/lib/python3.8/site-packages/airflow/models/taskinstance.py", line 433, in _execute_task
    result = execute_callable(context=context, **execute_callable_kwargs)
  File "/home/airflow/.local/lib/python3.8/site-packages/airflow/sensors/base.py", line 265, in execute
    raise e
  File "/home/airflow/.local/lib/python3.8/site-packages/airflow/sensors/base.py", line 247, in execute
    poke_return = self.poke(context)
  File "/home/airflow/.local/lib/python3.8/site-packages/airflow/sensors/filesystem.py", line 63, in poke
    hook = FSHook(self.fs_conn_id)
  File "/home/airflow/.local/lib/python3.8/site-packages/airflow/hooks/filesystem.py", line 64, in __init__
    conn = self.get_connection(fs_conn_id)
  File "/home/airflow/.local/lib/python3.8/site-packages/airflow/hooks/base.py", line 82, in get_connection
    conn = Connection.get_connection_from_secrets(conn_id)
  File "/home/airflow/.local/lib/python3.8/site-packages/airflow/models/connection.py", line 479, in get_connection_from_secrets
    raise AirflowNotFoundException(f"The conn_id `{conn_id}` isn't defined")
airflow.exceptions.AirflowNotFoundException: The conn_id `fs_default` isn't defined
[2025-06-07T10:52:21.731+0000] {taskinstance.py:1138} INFO - Marking task as UP_FOR_RETRY. dag_id=ecommerce_data_ingestion, task_id=wait_for_olist_customers_dataset, execution_date=20250606T010000, start_date=20250607T105218, end_date=20250607T105221
[2025-06-07T10:52:21.867+0000] {standard_task_runner.py:107} ERROR - Failed to execute job 24 for task wait_for_olist_customers_dataset (The conn_id `fs_default` isn't defined; 296)
[2025-06-07T10:52:22.023+0000] {local_task_job_runner.py:234} INFO - Task exited with return code 1
[2025-06-07T10:52:23.538+0000] {taskinstance.py:3280} INFO - 0 downstream tasks scheduled from follow-on schedule check
