[2025-05-14 03:38:16,819] {taskinstance.py:1159} INFO - Dependencies all met for <TaskInstance: ecommerce_data_ingestion.wait_for_olist_orders_dataset scheduled__2025-05-13T01:00:00+00:00 [queued]>
[2025-05-14 03:38:16,895] {taskinstance.py:1159} INFO - Dependencies all met for <TaskInstance: ecommerce_data_ingestion.wait_for_olist_orders_dataset scheduled__2025-05-13T01:00:00+00:00 [queued]>
[2025-05-14 03:38:16,899] {taskinstance.py:1356} INFO - 
--------------------------------------------------------------------------------
[2025-05-14 03:38:16,907] {taskinstance.py:1357} INFO - Starting attempt 2 of 2
[2025-05-14 03:38:16,907] {taskinstance.py:1358} INFO - 
--------------------------------------------------------------------------------
[2025-05-14 03:38:16,995] {taskinstance.py:1377} INFO - Executing <Task(FileSensor): wait_for_olist_orders_dataset> on 2025-05-13 01:00:00+00:00
[2025-05-14 03:38:17,034] {standard_task_runner.py:52} INFO - Started process 231 to run task
[2025-05-14 03:38:17,260] {standard_task_runner.py:79} INFO - Running: ['***', 'tasks', 'run', 'ecommerce_data_ingestion', 'wait_for_olist_orders_dataset', 'scheduled__2025-05-13T01:00:00+00:00', '--job-id', '48', '--raw', '--subdir', 'DAGS_FOLDER/ecommerce_etl_dag.py', '--cfg-path', '/tmp/tmpiohyz_yv', '--error-file', '/tmp/tmpvcqlzlhx']
[2025-05-14 03:38:17,283] {standard_task_runner.py:80} INFO - Job 48: Subtask wait_for_olist_orders_dataset
[2025-05-14 03:38:17,886] {task_command.py:369} INFO - Running <TaskInstance: ecommerce_data_ingestion.wait_for_olist_orders_dataset scheduled__2025-05-13T01:00:00+00:00 [running]> on host 3360c9d70daf
[2025-05-14 03:38:18,872] {taskinstance.py:1569} INFO - Exporting the following env vars:
AIRFLOW_CTX_DAG_OWNER=***
AIRFLOW_CTX_DAG_ID=ecommerce_data_ingestion
AIRFLOW_CTX_TASK_ID=wait_for_olist_orders_dataset
AIRFLOW_CTX_EXECUTION_DATE=2025-05-13T01:00:00+00:00
AIRFLOW_CTX_TRY_NUMBER=2
AIRFLOW_CTX_DAG_RUN_ID=scheduled__2025-05-13T01:00:00+00:00
[2025-05-14 03:38:19,357] {taskinstance.py:1889} ERROR - Task failed with exception
Traceback (most recent call last):
  File "/home/airflow/.local/lib/python3.8/site-packages/airflow/sensors/base.py", line 277, in execute
    poke_return = self.poke(context)
  File "/home/airflow/.local/lib/python3.8/site-packages/airflow/sensors/filesystem.py", line 55, in poke
    hook = FSHook(self.fs_conn_id)
  File "/home/airflow/.local/lib/python3.8/site-packages/airflow/hooks/filesystem.py", line 38, in __init__
    conn = self.get_connection(conn_id)
  File "/home/airflow/.local/lib/python3.8/site-packages/airflow/hooks/base.py", line 67, in get_connection
    conn = Connection.get_connection_from_secrets(conn_id)
  File "/home/airflow/.local/lib/python3.8/site-packages/airflow/models/connection.py", line 430, in get_connection_from_secrets
    raise AirflowNotFoundException(f"The conn_id `{conn_id}` isn't defined")
airflow.exceptions.AirflowNotFoundException: The conn_id `fs_default` isn't defined
[2025-05-14 03:38:19,510] {taskinstance.py:1395} INFO - Marking task as FAILED. dag_id=ecommerce_data_ingestion, task_id=wait_for_olist_orders_dataset, execution_date=20250513T010000, start_date=20250514T033816, end_date=20250514T033819
[2025-05-14 03:38:19,655] {standard_task_runner.py:92} ERROR - Failed to execute job 48 for task wait_for_olist_orders_dataset (The conn_id `fs_default` isn't defined; 231)
[2025-05-14 03:38:19,738] {local_task_job.py:156} INFO - Task exited with return code 1
[2025-05-14 03:38:20,642] {local_task_job.py:84} ERROR - Received SIGTERM. Terminating subprocesses
[2025-05-14 03:38:20,664] {local_task_job.py:156} INFO - Task exited with return code 143
[2025-05-14 03:38:20,914] {local_task_job.py:273} INFO - 0 downstream tasks scheduled from follow-on schedule check
