[2025-06-07T10:52:17.857+0000] {taskinstance.py:1956} INFO - Dependencies all met for dep_context=non-requeueable deps ti=<TaskInstance: ecommerce_data_ingestion.wait_for_olist_orders_dataset manual__2025-06-07T10:51:35.349075+00:00 [queued]>
[2025-06-07T10:52:17.963+0000] {taskinstance.py:1956} INFO - Dependencies all met for dep_context=requeueable deps ti=<TaskInstance: ecommerce_data_ingestion.wait_for_olist_orders_dataset manual__2025-06-07T10:51:35.349075+00:00 [queued]>
[2025-06-07T10:52:17.966+0000] {taskinstance.py:2170} INFO - Starting attempt 1 of 2
[2025-06-07T10:52:18.120+0000] {taskinstance.py:2191} INFO - Executing <Task(FileSensor): wait_for_olist_orders_dataset> on 2025-06-07 10:51:35.349075+00:00
[2025-06-07T10:52:18.498+0000] {standard_task_runner.py:60} INFO - Started process 293 to run task
[2025-06-07T10:52:18.549+0000] {standard_task_runner.py:87} INFO - Running: ['***', 'tasks', 'run', 'ecommerce_data_ingestion', 'wait_for_olist_orders_dataset', 'manual__2025-06-07T10:51:35.349075+00:00', '--job-id', '22', '--raw', '--subdir', 'DAGS_FOLDER/ecommerce_etl_dag.py', '--cfg-path', '/tmp/tmphtkjbxmw']
[2025-06-07T10:52:18.742+0000] {standard_task_runner.py:88} INFO - Job 22: Subtask wait_for_olist_orders_dataset
[2025-06-07T10:52:19.950+0000] {task_command.py:423} INFO - Running <TaskInstance: ecommerce_data_ingestion.wait_for_olist_orders_dataset manual__2025-06-07T10:51:35.349075+00:00 [running]> on host ab0825485965
[2025-06-07T10:52:20.816+0000] {taskinstance.py:2480} INFO - Exporting env vars: AIRFLOW_CTX_DAG_OWNER='***' AIRFLOW_CTX_DAG_ID='ecommerce_data_ingestion' AIRFLOW_CTX_TASK_ID='wait_for_olist_orders_dataset' AIRFLOW_CTX_EXECUTION_DATE='2025-06-07T10:51:35.349075+00:00' AIRFLOW_CTX_TRY_NUMBER='1' AIRFLOW_CTX_DAG_RUN_ID='manual__2025-06-07T10:51:35.349075+00:00'
[2025-06-07T10:52:21.023+0000] {taskinstance.py:2698} ERROR - Task failed with exception
Traceback (most recent call last):
  File "/home/airflow/.local/lib/python3.8/site-packages/airflow/models/taskinstance.py", line 433, in _execute_task
    result = execute_callable(context=context, **execute_callable_kwargs)
  File "/home/airflow/.local/lib/python3.8/site-packages/airflow/sensors/base.py", line 265, in execute
    raise e
  File "/home/airflow/.local/lib/python3.8/site-packages/airflow/sensors/base.py", line 247, in execute
    poke_return = self.poke(context)
  File "/home/airflow/.local/lib/python3.8/site-packages/airflow/sensors/filesystem.py", line 63, in poke
    hook = FSHook(self.fs_conn_id)
  File "/home/airflow/.local/lib/python3.8/site-packages/airflow/hooks/filesystem.py", line 64, in __init__
    conn = self.get_connection(fs_conn_id)
  File "/home/airflow/.local/lib/python3.8/site-packages/airflow/hooks/base.py", line 82, in get_connection
    conn = Connection.get_connection_from_secrets(conn_id)
  File "/home/airflow/.local/lib/python3.8/site-packages/airflow/models/connection.py", line 479, in get_connection_from_secrets
    raise AirflowNotFoundException(f"The conn_id `{conn_id}` isn't defined")
airflow.exceptions.AirflowNotFoundException: The conn_id `fs_default` isn't defined
[2025-06-07T10:52:21.045+0000] {taskinstance.py:1138} INFO - Marking task as UP_FOR_RETRY. dag_id=ecommerce_data_ingestion, task_id=wait_for_olist_orders_dataset, execution_date=20250607T105135, start_date=20250607T105217, end_date=20250607T105221
[2025-06-07T10:52:21.183+0000] {standard_task_runner.py:107} ERROR - Failed to execute job 22 for task wait_for_olist_orders_dataset (The conn_id `fs_default` isn't defined; 293)
[2025-06-07T10:52:21.323+0000] {local_task_job_runner.py:234} INFO - Task exited with return code 1
[2025-06-07T10:52:21.751+0000] {taskinstance.py:3280} INFO - 0 downstream tasks scheduled from follow-on schedule check
