[2025-05-14 03:38:16,969] {taskinstance.py:1159} INFO - Dependencies all met for <TaskInstance: ecommerce_data_ingestion.wait_for_olist_customers_dataset manual__2025-05-14T03:25:30.365658+00:00 [queued]>
[2025-05-14 03:38:17,049] {taskinstance.py:1159} INFO - Dependencies all met for <TaskInstance: ecommerce_data_ingestion.wait_for_olist_customers_dataset manual__2025-05-14T03:25:30.365658+00:00 [queued]>
[2025-05-14 03:38:17,062] {taskinstance.py:1356} INFO - 
--------------------------------------------------------------------------------
[2025-05-14 03:38:17,064] {taskinstance.py:1357} INFO - Starting attempt 2 of 2
[2025-05-14 03:38:17,065] {taskinstance.py:1358} INFO - 
--------------------------------------------------------------------------------
[2025-05-14 03:38:17,377] {taskinstance.py:1377} INFO - Executing <Task(FileSensor): wait_for_olist_customers_dataset> on 2025-05-14 03:25:30.365658+00:00
[2025-05-14 03:38:17,601] {standard_task_runner.py:79} INFO - Running: ['***', 'tasks', 'run', 'ecommerce_data_ingestion', 'wait_for_olist_customers_dataset', 'manual__2025-05-14T03:25:30.365658+00:00', '--job-id', '49', '--raw', '--subdir', 'DAGS_FOLDER/ecommerce_etl_dag.py', '--cfg-path', '/tmp/tmpvt3jf0jv', '--error-file', '/tmp/tmpa_nvtyml']
[2025-05-14 03:38:17,620] {standard_task_runner.py:80} INFO - Job 49: Subtask wait_for_olist_customers_dataset
[2025-05-14 03:38:17,560] {standard_task_runner.py:52} INFO - Started process 234 to run task
[2025-05-14 03:38:18,143] {task_command.py:369} INFO - Running <TaskInstance: ecommerce_data_ingestion.wait_for_olist_customers_dataset manual__2025-05-14T03:25:30.365658+00:00 [running]> on host 3360c9d70daf
[2025-05-14 03:38:18,859] {taskinstance.py:1569} INFO - Exporting the following env vars:
AIRFLOW_CTX_DAG_OWNER=***
AIRFLOW_CTX_DAG_ID=ecommerce_data_ingestion
AIRFLOW_CTX_TASK_ID=wait_for_olist_customers_dataset
AIRFLOW_CTX_EXECUTION_DATE=2025-05-14T03:25:30.365658+00:00
AIRFLOW_CTX_TRY_NUMBER=2
AIRFLOW_CTX_DAG_RUN_ID=manual__2025-05-14T03:25:30.365658+00:00
[2025-05-14 03:38:19,336] {taskinstance.py:1889} ERROR - Task failed with exception
Traceback (most recent call last):
  File "/home/airflow/.local/lib/python3.8/site-packages/airflow/sensors/base.py", line 277, in execute
    poke_return = self.poke(context)
  File "/home/airflow/.local/lib/python3.8/site-packages/airflow/sensors/filesystem.py", line 55, in poke
    hook = FSHook(self.fs_conn_id)
  File "/home/airflow/.local/lib/python3.8/site-packages/airflow/hooks/filesystem.py", line 38, in __init__
    conn = self.get_connection(conn_id)
  File "/home/airflow/.local/lib/python3.8/site-packages/airflow/hooks/base.py", line 67, in get_connection
    conn = Connection.get_connection_from_secrets(conn_id)
  File "/home/airflow/.local/lib/python3.8/site-packages/airflow/models/connection.py", line 430, in get_connection_from_secrets
    raise AirflowNotFoundException(f"The conn_id `{conn_id}` isn't defined")
airflow.exceptions.AirflowNotFoundException: The conn_id `fs_default` isn't defined
[2025-05-14 03:38:19,456] {taskinstance.py:1395} INFO - Marking task as FAILED. dag_id=ecommerce_data_ingestion, task_id=wait_for_olist_customers_dataset, execution_date=20250514T032530, start_date=20250514T033816, end_date=20250514T033819
[2025-05-14 03:38:19,632] {standard_task_runner.py:92} ERROR - Failed to execute job 49 for task wait_for_olist_customers_dataset (The conn_id `fs_default` isn't defined; 234)
[2025-05-14 03:38:19,850] {local_task_job.py:156} INFO - Task exited with return code 1
[2025-05-14 03:38:20,674] {local_task_job.py:84} ERROR - Received SIGTERM. Terminating subprocesses
[2025-05-14 03:38:20,686] {local_task_job.py:156} INFO - Task exited with return code 143
[2025-05-14 03:38:21,153] {local_task_job.py:273} INFO - 0 downstream tasks scheduled from follow-on schedule check
